{"changes": {"state": {"new": "open", "old": "closed"}}, "links": {"self": {"href": "data/repositories/osrf/subt/issues/224/changes/54611793.json"}, "html": {"href": "#!/osrf/subt/issues/224#comment-54611793"}}, "issue": {"links": {"self": {"href": "data/repositories/osrf/subt/issues/224.json"}}, "type": "issue", "id": 224, "repository": {"links": {"self": {"href": "data/repositories/osrf/subt.json"}, "html": {"href": "#!/osrf/subt"}, "avatar": {"href": "data/bytebucket.org/ravatar/{3c95f6ad-c304-407c-b838-09597d836552}ts=2272898"}}, "type": "repository", "name": "subt", "full_name": "osrf/subt", "uuid": "{3c95f6ad-c304-407c-b838-09597d836552}"}, "title": "/subt/pose_from_artifact_origin after return from tunnel?"}, "created_on": "2019-10-31T08:37:18.607685+00:00", "user": {"display_name": "Martin Dlouhy", "uuid": "{27de76db-249c-44be-9eb8-91a3b17bf0d7}", "links": {"self": {"href": "https://api.bitbucket.org/2.0/users/%7B27de76db-249c-44be-9eb8-91a3b17bf0d7%7D"}, "html": {"href": "https://bitbucket.org/%7B27de76db-249c-44be-9eb8-91a3b17bf0d7%7D/"}, "avatar": {"href": "data/secure.gravatar.com/avatar/85a9b1d43839b393296feb3b35a2e577d=httpsavatar-management--avatars.us-west-2.prod.public.atl-paas.netinitialsMD-1.png"}}, "nickname": "robotikacz", "type": "user", "account_id": "557058:490c665b-b69c-40f3-80ea-64f20747efc4"}, "message": {"raw": "I would re-open this issue and change it to bug, because last night I was testing new \"Urban Qualification\" world (robotika, ver2509urban0, ea772540-0d21-46b1-86fa-0e80986f4a0a), robots C and D, where C probably never left the staging area and D returned and then circled many times ... but was not able to query origin any more.\n328.476000000 ERROR /subt_solution [/home/developer/subt_solution/src/subt_seed/src/subt_seed_node.cc:284(Update)] [topics: ] Failed to call pose_from_artifact_origin service, robot may not exist, be outside staging area, or the service is not available.", "markup": "markdown", "html": "<p>I would re-open this issue and change it to bug, because last night I was testing new \"Urban Qualification\" world (robotika, ver2509urban0, <a href=\"#!/osrf/subt/commits/ea772540\" rel=\"nofollow\" class=\"ap-connect-link\">ea772540</a>-0d21-46b1-86fa-0e80986f4a0a), robots C and D, where C probably never left the staging area and D returned and then circled many times ... but was not able to query origin any more.\n328.<a href=\"#!/osrf/subt/commits/476000000\" rel=\"nofollow\" class=\"ap-connect-link\">476000000</a> ERROR /subt_solution [/home/developer/subt_solution/src/subt_seed/src/subt_seed_node.cc:284(Update)] [topics: ] Failed to call pose_from_artifact_origin service, robot may not exist, be outside staging area, or the service is not available.</p>", "type": "rendered"}, "type": "issue_change", "id": 54611793}