{"links": {"self": {"href": "data/repositories/osrf/subt/issues/165/comments/53696082.json"}, "html": {"href": "#!/osrf/subt/issues/165#comment-53696082"}}, "issue": {"links": {"self": {"href": "data/repositories/osrf/subt/issues/165.json"}}, "type": "issue", "id": 165, "repository": {"links": {"self": {"href": "data/repositories/osrf/subt.json"}, "html": {"href": "#!/osrf/subt"}, "avatar": {"href": "data/bytebucket.org/ravatar/{3c95f6ad-c304-407c-b838-09597d836552}ts=2272898"}}, "type": "repository", "name": "subt", "full_name": "osrf/subt", "uuid": "{3c95f6ad-c304-407c-b838-09597d836552}"}, "title": "Issue with subt_hello_world tutorial"}, "content": {"raw": "Hey Arthur,\n\nI am glad to see that you still remember my last problem. :\\)\n\nWell, I did fresh installation of 18.04. And also did all the setup installation on the Native Installation page.\n\nI did the libgoogle-glog-dev installation. It removes the earlier error. But found 2 below error logs.\n\n\u200c\n\n`[FATAL] [1567337888.012773662, 12.571000000]: Failed to create the dwa_local_planner/DWAPlannerROS planner, are you sure it is properly registered and that the containing library is built? Exception: According to the loaded plugin descriptions the class dwa_local_planner/DWAPlannerROS with base class type nav_core::BaseLocalPlanner does not exist. Declared types are  base_local_planner/TrajectoryPlannerROS`  \n`[alpha/move_base-13] process has died [pid 16814, exit code 1, cmd /opt/ros/melodic/lib/move_base/move_base map:=projected_map __name:=move_base __log:=/home/baila/.ros/log/38eaf2fe-c9b8-11e9-9100-68a3c4a1e180/alpha-move_base-13.log].`  \n`log file: /home/baila/.ros/log/38eaf2fe-c9b8-11e9-9100-68a3c4a1e180/alpha-move_base-13*.log`\n\n\u200c\n\nand\n\n\u200c\n\n`[ERROR] [1567338070.684413, 37.394000]: bad callback: <bound method Detector.image_cb of <main.Detector instance at 0x7fe7a0769f38>>`  \n`Traceback (most recent call last):`  \n`File \"/opt/ros/melodic/lib/python2.7/dist-packages/rospy/topics.py\", line 750, in _invoke_callback`  \n`cb(msg)`  \n`File \"/home/baila/subt_hello_world/catkin_build_ws/src/tensorflow_object_detector/scripts/detect_ros.py\", line 99, in image_cb`  \n`(boxes, scores, classes, num_detections) = self.sess.run([boxes, scores, classes, num_detections],`  \n`AttributeError: Detector instance has no attribute 'sess'`\n\nany clue?", "markup": "markdown", "html": "<p>Hey Arthur,</p>\n<p>I am glad to see that you still remember my last problem. :)</p>\n<p>Well, I did fresh installation of 18.04. And also did all the setup installation on the Native Installation page.</p>\n<p>I did the libgoogle-glog-dev installation. It removes the earlier error. But found 2 below error logs.</p>\n<p>\u200c</p>\n<p><code>[FATAL] [1567337888.012773662, 12.571000000]: Failed to create the dwa_local_planner/DWAPlannerROS planner, are you sure it is properly registered and that the containing library is built? Exception: According to the loaded plugin descriptions the class dwa_local_planner/DWAPlannerROS with base class type nav_core::BaseLocalPlanner does not exist. Declared types are  base_local_planner/TrajectoryPlannerROS</code><br />\n<code>[alpha/move_base-13] process has died [pid 16814, exit code 1, cmd /opt/ros/melodic/lib/move_base/move_base map:=projected_map __name:=move_base __log:=/home/baila/.ros/log/38eaf2fe-c9b8-11e9-9100-68a3c4a1e180/alpha-move_base-13.log].</code><br />\n<code>log file: /home/baila/.ros/log/38eaf2fe-c9b8-11e9-9100-68a3c4a1e180/alpha-move_base-13*.log</code></p>\n<p>\u200c</p>\n<p>and</p>\n<p>\u200c</p>\n<p><code>[ERROR] [1567338070.684413, 37.394000]: bad callback: &lt;bound method Detector.image_cb of &lt;main.Detector instance at 0x7fe7a0769f38&gt;&gt;</code><br />\n<code>Traceback (most recent call last):</code><br />\n<code>File \"/opt/ros/melodic/lib/python2.7/dist-packages/rospy/topics.py\", line 750, in _invoke_callback</code><br />\n<code>cb(msg)</code><br />\n<code>File \"/home/baila/subt_hello_world/catkin_build_ws/src/tensorflow_object_detector/scripts/detect_ros.py\", line 99, in image_cb</code><br />\n<code>(boxes, scores, classes, num_detections) = self.sess.run([boxes, scores, classes, num_detections],</code><br />\n<code>AttributeError: Detector instance has no attribute 'sess'</code></p>\n<p>any clue?</p>", "type": "rendered"}, "created_on": "2019-09-01T11:57:25.493701+00:00", "user": {"display_name": "baila", "uuid": "{22c52b82-0467-49e5-afbf-803525a87d06}", "links": {"self": {"href": "https://api.bitbucket.org/2.0/users/%7B22c52b82-0467-49e5-afbf-803525a87d06%7D"}, "html": {"href": "https://bitbucket.org/%7B22c52b82-0467-49e5-afbf-803525a87d06%7D/"}, "avatar": {"href": "data/secure.gravatar.com/avatar/e82780891a1e938f0bf3a529adc858a5d=httpsavatar-management--avatars.us-west-2.prod.public.atl-paas.netinitialsB-3.png"}}, "nickname": "baila", "type": "user", "account_id": "557058:42fc2023-4935-4b2e-8079-075649866124"}, "updated_on": null, "type": "issue_comment", "id": 53696082}